<robot
  name="hdf_model">
  <link
    name="base_link">
    <inertial>
      <origin
        xyz="0.0710712962197142 -0.000137753873757876 -0.0472356807568853"
        rpy="0 0 0" />
      <mass
        value="2.8968201286225" />
      <inertia
        ixx="0.0435515415861913"
        ixy="-7.54353183930224E-05"
        ixz="-0.0120679749993695"
        iyy="0.0775488218939522"
        iyz="3.02473586563858E-05"
        izz="0.105083705856808" />
    </inertial>
    <visual>
      <origin
        xyz="0 0 0"
        rpy="0 0 0" />
      <geometry>
        <mesh
          filename="package://hdf_model/meshes/base_link.STL" />
      </geometry>
      <material
        name="">
        <color
          rgba="0.792156862745098 0.819607843137255 0.933333333333333 1" />
      </material>
    </visual>
    <collision>
      <origin
        xyz="0 0 0"
        rpy="0 0 0" />
      <geometry>
        <mesh
          filename="package://hdf_model/meshes/base_link.STL" />
      </geometry>
    </collision>
  </link>
  <link
    name="front_left_wheel_link">
    <inertial>
      <origin
        xyz="0 -6.3295189589585E-07 0"
        rpy="0 0 0" />
      <mass
        value="0.482131555796721" />
      <inertia
        ixx="0.000893944886202995"
        ixy="-4.51240238343766E-20"
        ixz="1.17525821431534E-20"
        iyy="0.00168163508591572"
        iyz="-3.96864618172625E-21"
        izz="0.000893944886202995" />
    </inertial>
    <visual>
      <origin
        xyz="0 0 0"
        rpy="0 0 0" />
      <geometry>
        <mesh
          filename="package://hdf_model/meshes/front_left_wheel_link.STL" />
      </geometry>
      <material
        name="">
        <color
          rgba="0.294117647058824 0.294117647058824 0.294117647058824 1" />
      </material>
    </visual>
    <collision>
      <origin
        xyz="0 0 0"
        rpy="0 0 0" />
      <geometry>
        <mesh
          filename="package://hdf_model/meshes/front_left_wheel_link.STL" />
      </geometry>
    </collision>
  </link>
  <joint
    name="front_left_wheel_joint"
    type="continuous">
    <origin
      xyz="-0.0774999999999994 0.1925 -0.0930000000000001"
      rpy="1.29699056065384E-16 0.000304917468774119 3.60306029014719E-15" />
    <parent
      link="base_link" />
    <child
      link="front_left_wheel_link" />
    <axis
      xyz="0 -1 0" />
  </joint>
  <link
    name="front_right_wheel_link">
    <inertial>
      <origin
        xyz="0 -6.3295189589585E-07 0"
        rpy="0 0 0" />
      <mass
        value="0.482131555796721" />
      <inertia
        ixx="0.000893944886202993"
        ixy="-2.15673142206335E-20"
        ixz="-1.62630325872826E-19"
        iyy="0.00168163508591572"
        iyz="1.16692499357991E-20"
        izz="0.000893944886202994" />
    </inertial>
    <visual>
      <origin
        xyz="0 0 0"
        rpy="0 0 0" />
      <geometry>
        <mesh
          filename="package://hdf_model/meshes/front_right_wheel_link.STL" />
      </geometry>
      <material
        name="">
        <color
          rgba="0.294117647058824 0.294117647058824 0.294117647058824 1" />
      </material>
    </visual>
    <collision>
      <origin
        xyz="0 0 0"
        rpy="0 0 0" />
      <geometry>
        <mesh
          filename="package://hdf_model/meshes/front_right_wheel_link.STL" />
      </geometry>
    </collision>
  </link>
  <joint
    name="front_right_wheel_joint"
    type="continuous">
    <origin
      xyz="-0.0774999999999989 -0.192500000000001 -0.0930000000000001"
      rpy="1.54507720819671E-16 -0.580624336864947 3.51749903859331E-15" />
    <parent
      link="base_link" />
    <child
      link="front_right_wheel_link" />
    <axis
      xyz="0 -1 0" />
  </joint>
  <link
    name="laser_link">
    <inertial>
      <origin
        xyz="-8.54230302427539E-05 6.72214995819098E-05 0.0299775216686896"
        rpy="0 0 0" />
      <mass
        value="0.149621221992963" />
      <inertia
        ixx="8.91590299505418E-05"
        ixy="8.67289898114126E-08"
        ixz="4.3986338046771E-08"
        iyy="8.93716564388956E-05"
        iyz="-2.34056549904993E-07"
        izz="5.2029602781235E-05" />
    </inertial>
    <visual>
      <origin
        xyz="0 0 0"
        rpy="0 0 0" />
      <geometry>
        <mesh
          filename="package://hdf_model/meshes/laser_link.STL" />
      </geometry>
      <material
        name="">
        <color
          rgba="0.792156862745098 0.819607843137255 0.933333333333333 1" />
      </material>
    </visual>
    <collision>
      <origin
        xyz="0 0 0"
        rpy="0 0 0" />
      <geometry>
        <mesh
          filename="package://hdf_model/meshes/laser_link.STL" />
      </geometry>
    </collision>
  </link>
  <joint
    name="laser_joint"
    type="fixed">
    <origin
      xyz="0.220650000000521 0 0"
      rpy="2.01948391736579E-28 2.46519014539409E-32 5.03235953499442E-12" />
    <parent
      link="base_link" />
    <child
      link="laser_link" />
    <axis
      xyz="0 0 0" />
  </joint>
</robot>